<mujoco model="graspnet_scene_0000">
        <compiler angle="radian" meshdir="/" autolimits="true"/>

        <option integrator="implicitfast" impratio="10" cone="elliptic" timestep="0.002" noslip_iterations="3"/>

        <visual>
          <global offwidth="1280" offheight="720"/>
        </visual>

        <default>
          <default class="panda">
            <material specular="0.5" shininess="0.25"/>
            <joint armature="0.1" damping="1" axis="0 0 1" range="-2.8973 2.8973"/>
            <general dyntype="none" biastype="affine" ctrlrange="-2.8973 2.8973" forcerange="-87 87"/>
            <default class="finger">
              <joint axis="0 1 0" type="slide" range="0 0.04"/>
            </default>
            <default class="visual">
              <geom type="mesh" contype="0" conaffinity="0" group="2"/>
            </default>
            <default class="collision">
              <geom type="mesh" group="3" friction="2 0.05 0.01"/>
              <default class="fingertip_pad_collision_1">
                <geom type="box" size="0.0085 0.004 0.0085" pos="0 0.0055 0.0445" friction="2 0.05 0.01"/>
              </default>
              <default class="fingertip_pad_collision_2">
                <geom type="box" size="0.003 0.002 0.003" pos="0.0055 0.002 0.05" friction="2 0.05 0.01"/>
              </default>
              <default class="fingertip_pad_collision_3">
                <geom type="box" size="0.003 0.002 0.003" pos="-0.0055 0.002 0.05" friction="2 0.05 0.01"/>
              </default>
              <default class="fingertip_pad_collision_4">
                <geom type="box" size="0.003 0.002 0.0035" pos="0.0055 0.002 0.0395" friction="2 0.05 0.01"/>
              </default>
              <default class="fingertip_pad_collision_5">
                <geom type="box" size="0.003 0.002 0.0035" pos="-0.0055 0.002 0.0395" friction="2 0.05 0.01"/>
              </default>
            </default>
          </default>
        </default>

        <asset>
            <material class="panda" name="white"     rgba="1 1 1 1"/>
            <material class="panda" name="off_white" rgba="0.901961 0.921569 0.929412 1"/>
            <material class="panda" name="black"     rgba="0.25 0.25 0.25 1"/>

            <mesh name="hand_c"   file="/home/sbehnam/Project/grasp2sim/franka_emika_panda/assets/hand.stl"/>
            <mesh name="hand_0"   file="/home/sbehnam/Project/grasp2sim/franka_emika_panda/assets/hand_0.obj"/>
            <mesh name="hand_1"   file="/home/sbehnam/Project/grasp2sim/franka_emika_panda/assets/hand_1.obj"/>
            <mesh name="hand_2"   file="/home/sbehnam/Project/grasp2sim/franka_emika_panda/assets/hand_2.obj"/>
            <mesh name="hand_3"   file="/home/sbehnam/Project/grasp2sim/franka_emika_panda/assets/hand_3.obj"/>
            <mesh name="hand_4"   file="/home/sbehnam/Project/grasp2sim/franka_emika_panda/assets/hand_4.obj"/>
            <mesh name="finger_0" file="/home/sbehnam/Project/grasp2sim/franka_emika_panda/assets/finger_0.obj"/>
            <mesh name="finger_1" file="/home/sbehnam/Project/grasp2sim/franka_emika_panda/assets/finger_1.obj"/>

    <mesh name="vis_obj_005" file="/home/sbehnam/models/005/textured.obj"/>
    <mesh name="col_obj_005_00" file="/home/sbehnam/models/005/coacd_part_00.stl"/>
    <mesh name="col_obj_005_01" file="/home/sbehnam/models/005/coacd_part_01.stl"/>
    <mesh name="col_obj_005_02" file="/home/sbehnam/models/005/coacd_part_02.stl"/>
    <mesh name="col_obj_005_03" file="/home/sbehnam/models/005/coacd_part_03.stl"/>
        </asset>

        <worldbody>
            <light directional="true" pos="0 0 2" dir="0 0 -1" diffuse="1 1 1"/>

            <!-- Table -->
            <body name="table" pos="0 0 -0.01">
              <geom type="box" size="0.5 0.5 0.01" rgba="0.8 0.7 0.6 1"
                    contype="1" conaffinity="1"/>
            </body>

            <body name="marker_tw" mocap="true" pos="0 0 0">
              <geom type="sphere" size="0.006" rgba="0.5 0.3 1 0.7"
                    contype="0" conaffinity="0" group="2"/>
            </body>
            <body name="marker_theo" mocap="true" pos="0 0 0">
              <geom type="sphere" size="0.006" rgba="0.85 0.35 0.2 0.7"
                    contype="0" conaffinity="0" group="2"/>
            </body>

            <!-- Hand: kinematic base. Pose set from Python via model.body_pos/body_quat.
                 No freejoint, no mocap, no weld. Fingers remain dynamic. -->
            <body name="hand" childclass="panda" pos="0 0 0.5" quat="1 0 0 0">
                <inertial mass="0.73" pos="-0.01 0 0.03" diaginertia="0.001 0.0025 0.0017"/>
                <geom mesh="hand_0" material="off_white" class="visual"/>
                <geom mesh="hand_1" material="black"     class="visual"/>
                <geom mesh="hand_2" material="black"     class="visual"/>
                <geom mesh="hand_3" material="white"     class="visual"/>
                <geom mesh="hand_4" material="off_white" class="visual"/>
                <geom mesh="hand_c" class="collision"/>
                <body name="left_finger" pos="0 0 0.0584">
                  <inertial mass="0.015" pos="0 0 0" diaginertia="2.375e-6 2.375e-6 7.5e-7"/>
                  <joint name="finger_joint1" class="finger"/>
                  <geom mesh="finger_0" material="off_white" class="visual"/>
                  <geom mesh="finger_1" material="black"     class="visual"/>
                  <geom mesh="finger_0" class="collision"/>
                  <geom class="fingertip_pad_collision_1"/>
                  <geom class="fingertip_pad_collision_2"/>
                  <geom class="fingertip_pad_collision_3"/>
                  <geom class="fingertip_pad_collision_4"/>
                  <geom class="fingertip_pad_collision_5"/>
                  <site name="left_tip"  pos="0 0.0015 0.0445" size="0.002" rgba="1 0 0 1"/>
                </body>
                <body name="right_finger" pos="0 0 0.0584" quat="0 0 0 1">
                  <inertial mass="0.015" pos="0 0 0" diaginertia="2.375e-6 2.375e-6 7.5e-7"/>
                  <joint name="finger_joint2" class="finger"/>
                  <geom mesh="finger_0" material="off_white" class="visual"/>
                  <geom mesh="finger_1" material="black"     class="visual"/>
                  <geom mesh="finger_0" class="collision"/>
                  <geom class="fingertip_pad_collision_1"/>
                  <geom class="fingertip_pad_collision_2"/>
                  <geom class="fingertip_pad_collision_3"/>
                  <geom class="fingertip_pad_collision_4"/>
                  <geom class="fingertip_pad_collision_5"/>
                  <site name="right_tip" pos="0 0.0015 0.0445" size="0.002" rgba="0 1 0 1"/>
                </body>
            </body>

        <!-- Scene objects -->
        
                <body name="obj_005" pos="-0.1267 -0.1008 0.0127"
                      quat="0.0851 0.0652 -0.0280 0.9938">
                  <joint type="free" damping="0.2"/>
                  <geom type="mesh" mesh="vis_obj_005" contype="0" conaffinity="0" group="2"/>
                  <geom type="mesh" mesh="col_obj_005_00" contype="1" conaffinity="1" group="3" friction="1.5 0.05 0.001" solimp="0.99 0.999 0.001" solref="0.001 1" condim="4"/>
                  <geom type="mesh" mesh="col_obj_005_01" contype="1" conaffinity="1" group="3" friction="1.5 0.05 0.001" solimp="0.99 0.999 0.001" solref="0.001 1" condim="4"/>
                  <geom type="mesh" mesh="col_obj_005_02" contype="1" conaffinity="1" group="3" friction="1.5 0.05 0.001" solimp="0.99 0.999 0.001" solref="0.001 1" condim="4"/>
                  <geom type="mesh" mesh="col_obj_005_03" contype="1" conaffinity="1" group="3" friction="1.5 0.05 0.001" solimp="0.99 0.999 0.001" solref="0.001 1" condim="4"/>
                </body>
        </worldbody>

          <contact>
            <exclude body1="hand" body2="left_finger"/>
            <exclude body1="hand" body2="right_finger"/>
          </contact>

          <equality>
            <!-- Keep fingers symmetric. NO weld: hand base is kinematic. -->
            <joint joint1="finger_joint1" joint2="finger_joint2"
                   solimp="0.95 0.99 0.001" solref="0.005 1"/>
          </equality>

          <tendon>
            <fixed name="split">
              <joint joint="finger_joint1" coef="0.5"/>
              <joint joint="finger_joint2" coef="0.5"/>
            </fixed>
          </tendon>

          <actuator>
            <general class="panda" name="actuator8" tendon="split" forcerange="-300 300"
                      ctrlrange="0 255" gainprm="0.04 0 0" biasprm="0 -300 -30"/>
          </actuator>

        </mujoco>
        